-04-14 20:22:29,679 - sentence_transformers.SentenceTransformer - INFO - Load pretrained SentenceTransformer: emrecan/bert-base-turkish-cased-mean-nli-stsb-tr
2025-04-14 20:22:30,792 - trendyol.trendyol_api_client - INFO - Getting required attributes for category 2921
2025-04-14 20:22:31,421 - trendyol.trendyol_api_client - ERROR - Error in send_lcwaikiki_to_trendyol: column trendyol_trendyolproduct.cargo_company_id does not exist
LINE 1: ... "trendyol_trendyolproduct"."dimensional_weight", "trendyol_...
                                                             ^

2025-04-14 20:22:31,421 - trendyol.trendyol_api_client - ERROR - column trendyol_trendyolproduct.cargo_company_id does not exist
LINE 1: ... "trendyol_trendyolproduct"."dimensional_weight", "trendyol_...
                                                             ^
Traceback (most recent call last):
  File "/home/runner/workspace/.pythonlibs/lib/python3.11/site-packages/django/db/backends/utils.py", line 105, in _execute
    return self.cursor.execute(sql, params)
           ^^^^^^^^^^^^^^^^^^^^^^^^^^^^^^^^
psycopg2.errors.UndefinedColumn: column trendyol_trendyolproduct.cargo_company_id does not exist
LINE 1: ... "trendyol_trendyolproduct"."dimensional_weight", "trendyol_...
                                                             ^


The above exception was the direct cause of the following exception:

Traceback (most recent call last):
  File "/home/runner/workspace/mainscrpr/trendyol/trendyol_api_client.py", line 744, in send_lcwaikiki_to_trendyol
    ).first()
      ^^^^^^^
  File "/home/runner/workspace/.pythonlibs/lib/python3.11/site-packages/django/db/models/query.py", line 1104, in first
    for obj in queryset[:1]:
  File "/home/runner/workspace/.pythonlibs/lib/python3.11/site-packages/django/db/models/query.py", line 384, in __iter__
    self._fetch_all()
  File "/home/runner/workspace/.pythonlibs/lib/python3.11/site-packages/django/db/models/query.py", line 1935, in _fetch_all
    self._result_cache = list(self._iterable_class(self))
                         ^^^^^^^^^^^^^^^^^^^^^^^^^^^^^^^^
  File "/home/runner/workspace/.pythonlibs/lib/python3.11/site-packages/django/db/models/query.py", line 91, in __iter__
    results = compiler.execute_sql(
              ^^^^^^^^^^^^^^^^^^^^^
  File "/home/runner/workspace/.pythonlibs/lib/python3.11/site-packages/django/db/models/sql/compiler.py", line 1622, in execute_sql
    cursor.execute(sql, params)
  File "/home/runner/workspace/.pythonlibs/lib/python3.11/site-packages/django/db/backends/utils.py", line 122, in execute
    return super().execute(sql, params)
           ^^^^^^^^^^^^^^^^^^^^^^^^^^^^
  File "/home/runner/workspace/.pythonlibs/lib/python3.11/site-packages/django/db/backends/utils.py", line 79, in execute
    return self._execute_with_wrappers(
           ^^^^^^^^^^^^^^^^^^^^^^^^^^^^
  File "/home/runner/workspace/.pythonlibs/lib/python3.11/site-packages/django/db/backends/utils.py", line 92, in _execute_with_wrappers
    return executor(sql, params, many, context)
           ^^^^^^^^^^^^^^^^^^^^^^^^^^^^^^^^^^^^
  File "/home/runner/workspace/.pythonlibs/lib/python3.11/site-packages/django/db/backends/utils.py", line 100, in _execute
    with self.db.wrap_database_errors:
  File "/home/runner/workspace/.pythonlibs/lib/python3.11/site-packages/django/db/utils.py", line 91, in __exit__
    raise dj_exc_value.with_traceback(traceback) from exc_value
  File "/home/runner/workspace/.pythonlibs/lib/python3.11/site-packages/django/db/backends/utils.py", line 105, in _execute
    return self.cursor.execute(sql, params)
           ^^^^^^^^^^^^^^^^^^^^^^^^^^^^^^^^
django.db.utils.ProgrammingError: column trendyol_trendyolproduct.cargo_company_id does not exist
LINE 1: ... "trendyol_trendyolproduct"."dimensional_weight", "trendyol_...